******************************************************************************************
29/08/2021 23:39:54
Traceback (most recent call last):
  File "/Applications/Xcode.app/Contents/Developer/Library/Frameworks/Python3.framework/Versions/3.8/lib/python3.8/encodings/idna.py", line 165, in encode
    raise UnicodeError("label empty or too long")
UnicodeError: label empty or too long

The above exception was the direct cause of the following exception:

Traceback (most recent call last):
  File "/Users/lucabonamino/dev/BruteSniffing_Fisher/main.py", line 21, in main
    session.start()
  File "/Users/lucabonamino/dev/BruteSniffing_Fisher/modules/controller.py", line 86, in start
    self.attack.run()
  File "/Users/lucabonamino/dev/BruteSniffing_Fisher/modules/controller.py", line 100, in run
    attack.run()
  File "/Users/lucabonamino/dev/BruteSniffing_Fisher/modules/Attack/core.py", line 36, in run
    class_.run()
  File "/Users/lucabonamino/dev/BruteSniffing_Fisher/modules/Attack/BruteForce/bruteforce.py", line 14, in run
    run()
  File "/Users/lucabonamino/dev/BruteSniffing_Fisher/modules/Attack/BruteForce/bruteforce.py", line 162, in run
    if function(email,passw,i, headers, url, proxychains):
  File "/Users/lucabonamino/dev/BruteSniffing_Fisher/modules/Attack/BruteForce/bruteforce.py", line 90, in function
    payload,cookie=create_form(headers,url)
  File "/Users/lucabonamino/dev/BruteSniffing_Fisher/modules/Attack/BruteForce/bruteforce.py", line 65, in create_form
    data=requests.get(url,headers=headers)
  File "/Users/lucabonamino/dev/BruteSniffing_Fisher/venv/lib/python3.8/site-packages/requests/api.py", line 75, in get
    return request('get', url, params=params, **kwargs)
  File "/Users/lucabonamino/dev/BruteSniffing_Fisher/venv/lib/python3.8/site-packages/requests/api.py", line 61, in request
    return session.request(method=method, url=url, **kwargs)
  File "/Users/lucabonamino/dev/BruteSniffing_Fisher/venv/lib/python3.8/site-packages/requests/sessions.py", line 532, in request
    settings = self.merge_environment_settings(
  File "/Users/lucabonamino/dev/BruteSniffing_Fisher/venv/lib/python3.8/site-packages/requests/sessions.py", line 711, in merge_environment_settings
    env_proxies = get_environ_proxies(url, no_proxy=no_proxy)
  File "/Users/lucabonamino/dev/BruteSniffing_Fisher/venv/lib/python3.8/site-packages/requests/utils.py", line 797, in get_environ_proxies
    if should_bypass_proxies(url, no_proxy=no_proxy):
  File "/Users/lucabonamino/dev/BruteSniffing_Fisher/venv/lib/python3.8/site-packages/requests/utils.py", line 781, in should_bypass_proxies
    bypass = proxy_bypass(parsed.hostname)
  File "/Applications/Xcode.app/Contents/Developer/Library/Frameworks/Python3.framework/Versions/3.8/lib/python3.8/urllib/request.py", line 2615, in proxy_bypass
    return proxy_bypass_macosx_sysconf(host)
  File "/Applications/Xcode.app/Contents/Developer/Library/Frameworks/Python3.framework/Versions/3.8/lib/python3.8/urllib/request.py", line 2592, in proxy_bypass_macosx_sysconf
    return _proxy_bypass_macosx_sysconf(host, proxy_settings)
  File "/Applications/Xcode.app/Contents/Developer/Library/Frameworks/Python3.framework/Versions/3.8/lib/python3.8/urllib/request.py", line 2565, in _proxy_bypass_macosx_sysconf
    hostIP = socket.gethostbyname(hostonly)
UnicodeError: encoding with 'idna' codec failed (UnicodeError: label empty or too long)


******************************************************************************************
30/08/2021 00:36:06
Traceback (most recent call last):
  File "/Users/lucabonamino/dev/BruteSniffing_Fisher/main.py", line 21, in main
    session.start()
  File "/Users/lucabonamino/dev/BruteSniffing_Fisher/modules/controller.py", line 73, in start
    elif x > max_index(self.dire.dict):
  File "/Users/lucabonamino/dev/BruteSniffing_Fisher/modules/controller.py", line 16, in max_index
    del dictionary[98]
KeyError: 98


******************************************************************************************
30/08/2021 00:36:21
Traceback (most recent call last):
  File "/Users/lucabonamino/dev/BruteSniffing_Fisher/main.py", line 21, in main
    session.start()
  File "/Users/lucabonamino/dev/BruteSniffing_Fisher/modules/controller.py", line 73, in start
    elif x > max_index(self.dire.dict):
  File "/Users/lucabonamino/dev/BruteSniffing_Fisher/modules/controller.py", line 16, in max_index
    del dictionary[98]
KeyError: 98


******************************************************************************************
30/08/2021 01:22:43
Traceback (most recent call last):
  File "main.py", line 21, in main
    session.start()
  File "/Users/lucabonamino/dev/BruteSniffing_Fisher/modules/controller.py", line 73, in start
    elif x > max_index(self.dire.dict):
  File "/Users/lucabonamino/dev/BruteSniffing_Fisher/modules/controller.py", line 16, in max_index
    del dictionary[98]
KeyError: 98


******************************************************************************************
30/08/2021 01:23:05
Traceback (most recent call last):
  File "main.py", line 21, in main
    session.start()
  File "/Users/lucabonamino/dev/BruteSniffing_Fisher/modules/controller.py", line 73, in start
    elif x > max_index(self.dire.dict):
  File "/Users/lucabonamino/dev/BruteSniffing_Fisher/modules/controller.py", line 16, in max_index
    del dictionary[98]
KeyError: 98


******************************************************************************************
30/08/2021 01:23:51
Traceback (most recent call last):
  File "main.py", line 21, in main
    session.start()
  File "/Users/lucabonamino/dev/BruteSniffing_Fisher/modules/controller.py", line 73, in start
    elif x > max_index(self.dire.dict):
  File "/Users/lucabonamino/dev/BruteSniffing_Fisher/modules/controller.py", line 16, in max_index
    del dictionary[98]
KeyError: 98


******************************************************************************************
30/08/2021 01:25:56
Traceback (most recent call last):
  File "main.py", line 21, in main
    session.start()
  File "/Users/lucabonamino/dev/BruteSniffing_Fisher/modules/controller.py", line 84, in start
    self.attack.run()
  File "/Users/lucabonamino/dev/BruteSniffing_Fisher/modules/controller.py", line 97, in run
    attack.run()
  File "/Users/lucabonamino/dev/BruteSniffing_Fisher/modules/Attack/core.py", line 35, in run
    class_.run()
TypeError: run() missing 1 required positional argument: 'self'


******************************************************************************************
30/08/2021 01:48:12
Traceback (most recent call last):
  File "main.py", line 21, in main
    session.start()
  File "/Users/lucabonamino/dev/BruteSniffing_Fisher/modules/controller.py", line 84, in start
    self.attack.run()
  File "/Users/lucabonamino/dev/BruteSniffing_Fisher/modules/controller.py", line 97, in run
    attack.run()
  File "/Users/lucabonamino/dev/BruteSniffing_Fisher/modules/Attack/core.py", line 35, in run
    class_.run()
  File "/Users/lucabonamino/dev/BruteSniffing_Fisher/modules/Attack/BruteForce/bruteforce.py", line 17, in run
    run()
  File "/Users/lucabonamino/dev/BruteSniffing_Fisher/modules/Attack/BruteForce/bruteforce.py", line 157, in run
    file = open(pass_file, 'r')
FileNotFoundError: [Errno 2] No such file or directory: 'data/BruteForce/bonamino.luca'


******************************************************************************************
28/07/2022 19:10:35
Traceback (most recent call last):
  File "main.py", line 21, in main
    session.start()
  File "/home/mintu/dev/BruteSniffing_Fisher/modules/controller.py", line 81, in start
    self.dire.change_directory(self.dirS[x], x)
IndexError: list index out of range


******************************************************************************************
28/07/2022 19:15:09
Traceback (most recent call last):
  File "/home/mintu/dev/BruteSniffing_Fisher/main.py", line 21, in main
    session.start()
  File "/home/mintu/dev/BruteSniffing_Fisher/modules/controller.py", line 81, in start
    self.dire.change_directory(self.dirS[x], x)
IndexError: list index out of range


******************************************************************************************
28/07/2022 19:23:19
Traceback (most recent call last):
  File "main.py", line 21, in main
    session.start()
  File "/home/mintu/dev/BruteSniffing_Fisher/modules/controller.py", line 84, in start
    self.attack.run()
  File "/home/mintu/dev/BruteSniffing_Fisher/modules/controller.py", line 97, in run
    attack.run()
  File "/home/mintu/dev/BruteSniffing_Fisher/modules/Attack/core.py", line 34, in run
    class_ = getattr(module, self.class_)
AttributeError: 'str' object has no attribute 'RSA'


******************************************************************************************
28/07/2022 19:23:42
Traceback (most recent call last):
  File "main.py", line 21, in main
    session.start()
  File "/home/mintu/dev/BruteSniffing_Fisher/modules/controller.py", line 84, in start
    self.attack.run()
  File "/home/mintu/dev/BruteSniffing_Fisher/modules/controller.py", line 97, in run
    attack.run()
  File "/home/mintu/dev/BruteSniffing_Fisher/modules/Attack/core.py", line 34, in run
    class_ = getattr(module, self.class_)
AttributeError: 'str' object has no attribute 'Rsa'


******************************************************************************************
28/07/2022 19:24:27
Traceback (most recent call last):
  File "main.py", line 21, in main
    session.start()
  File "/home/mintu/dev/BruteSniffing_Fisher/modules/controller.py", line 84, in start
    self.attack.run()
  File "/home/mintu/dev/BruteSniffing_Fisher/modules/controller.py", line 97, in run
    attack.run()
  File "/home/mintu/dev/BruteSniffing_Fisher/modules/Attack/core.py", line 34, in run
    class_ = getattr(module, self.class_)
AttributeError: module 'modules.Attack.rsa' has no attribute 'Rsa'


******************************************************************************************
11/08/2022 00:48:34
Traceback (most recent call last):
  File "/home/mintu/dev/BruteSniffing_Fisher/modules/Attack/rsa.py", line 47, in run
    x = str(input("> "))
KeyboardInterrupt

During handling of the above exception, another exception occurred:

Traceback (most recent call last):
  File "main.py", line 21, in main
    session.start()
  File "/home/mintu/dev/BruteSniffing_Fisher/modules/controller.py", line 84, in start
    self.attack.run()
  File "/home/mintu/dev/BruteSniffing_Fisher/modules/controller.py", line 97, in run
    attack.run()
  File "/home/mintu/dev/BruteSniffing_Fisher/modules/Attack/core.py", line 35, in run
    class_.run()
  File "/home/mintu/dev/BruteSniffing_Fisher/modules/Attack/rsa.py", line 20, in run
    run()
  File "/home/mintu/dev/BruteSniffing_Fisher/modules/Attack/rsa.py", line 52, in run
    Rsa.exit(c=c, connection=conn)
  File "/home/mintu/dev/BruteSniffing_Fisher/modules/Attack/rsa.py", line 39, in exit
    c.execute("DROP table keys")
sqlite3.OperationalError: no such table: keys


******************************************************************************************
11/08/2022 01:07:28
Traceback (most recent call last):
  File "main.py", line 21, in main
    session.start()
  File "/home/mintu/dev/BruteSniffing_Fisher/modules/controller.py", line 84, in start
    self.attack.run()
  File "/home/mintu/dev/BruteSniffing_Fisher/modules/controller.py", line 97, in run
    attack.run()
  File "/home/mintu/dev/BruteSniffing_Fisher/modules/Attack/core.py", line 23, in run
    module = importlib.import_module('modules.Attack.' + self.module)
  File "/usr/lib/python3.8/importlib/__init__.py", line 127, in import_module
    return _bootstrap._gcd_import(name[level:], package, level)
  File "<frozen importlib._bootstrap>", line 1014, in _gcd_import
  File "<frozen importlib._bootstrap>", line 991, in _find_and_load
  File "<frozen importlib._bootstrap>", line 975, in _find_and_load_unlocked
  File "<frozen importlib._bootstrap>", line 671, in _load_unlocked
  File "<frozen importlib._bootstrap_external>", line 848, in exec_module
  File "<frozen importlib._bootstrap>", line 219, in _call_with_frames_removed
  File "/home/mintu/dev/BruteSniffing_Fisher/modules/Attack/rsa.py", line 87, in <module>
    def encrypt(message):
  File "/home/mintu/dev/BruteSniffing_Fisher/venv/lib/python3.8/site-packages/click/decorators.py", line 308, in decorator
    _param_memo(f, OptionClass(param_decls, **option_attrs))
  File "/home/mintu/dev/BruteSniffing_Fisher/venv/lib/python3.8/site-packages/click/core.py", line 2495, in __init__
    super().__init__(param_decls, type=type, multiple=multiple, **attrs)
TypeError: __init__() got an unexpected keyword argument 'description'


