******************************************************************************************
29/08/2021 23:39:54
Traceback (most recent call last):
  File "/Applications/Xcode.app/Contents/Developer/Library/Frameworks/Python3.framework/Versions/3.8/lib/python3.8/encodings/idna.py", line 165, in encode
    raise UnicodeError("label empty or too long")
UnicodeError: label empty or too long

The above exception was the direct cause of the following exception:

Traceback (most recent call last):
  File "/Users/lucabonamino/dev/BruteSniffing_Fisher/main.py", line 21, in main
    session.start()
  File "/Users/lucabonamino/dev/BruteSniffing_Fisher/modules/controller.py", line 86, in start
    self.attack.run()
  File "/Users/lucabonamino/dev/BruteSniffing_Fisher/modules/controller.py", line 100, in run
    attack.run()
  File "/Users/lucabonamino/dev/BruteSniffing_Fisher/modules/Attack/core.py", line 36, in run
    class_.run()
  File "/Users/lucabonamino/dev/BruteSniffing_Fisher/modules/Attack/BruteForce/bruteforce.py", line 14, in run
    run()
  File "/Users/lucabonamino/dev/BruteSniffing_Fisher/modules/Attack/BruteForce/bruteforce.py", line 162, in run
    if function(email,passw,i, headers, url, proxychains):
  File "/Users/lucabonamino/dev/BruteSniffing_Fisher/modules/Attack/BruteForce/bruteforce.py", line 90, in function
    payload,cookie=create_form(headers,url)
  File "/Users/lucabonamino/dev/BruteSniffing_Fisher/modules/Attack/BruteForce/bruteforce.py", line 65, in create_form
    data=requests.get(url,headers=headers)
  File "/Users/lucabonamino/dev/BruteSniffing_Fisher/venv/lib/python3.8/site-packages/requests/api.py", line 75, in get
    return request('get', url, params=params, **kwargs)
  File "/Users/lucabonamino/dev/BruteSniffing_Fisher/venv/lib/python3.8/site-packages/requests/api.py", line 61, in request
    return session.request(method=method, url=url, **kwargs)
  File "/Users/lucabonamino/dev/BruteSniffing_Fisher/venv/lib/python3.8/site-packages/requests/sessions.py", line 532, in request
    settings = self.merge_environment_settings(
  File "/Users/lucabonamino/dev/BruteSniffing_Fisher/venv/lib/python3.8/site-packages/requests/sessions.py", line 711, in merge_environment_settings
    env_proxies = get_environ_proxies(url, no_proxy=no_proxy)
  File "/Users/lucabonamino/dev/BruteSniffing_Fisher/venv/lib/python3.8/site-packages/requests/utils.py", line 797, in get_environ_proxies
    if should_bypass_proxies(url, no_proxy=no_proxy):
  File "/Users/lucabonamino/dev/BruteSniffing_Fisher/venv/lib/python3.8/site-packages/requests/utils.py", line 781, in should_bypass_proxies
    bypass = proxy_bypass(parsed.hostname)
  File "/Applications/Xcode.app/Contents/Developer/Library/Frameworks/Python3.framework/Versions/3.8/lib/python3.8/urllib/request.py", line 2615, in proxy_bypass
    return proxy_bypass_macosx_sysconf(host)
  File "/Applications/Xcode.app/Contents/Developer/Library/Frameworks/Python3.framework/Versions/3.8/lib/python3.8/urllib/request.py", line 2592, in proxy_bypass_macosx_sysconf
    return _proxy_bypass_macosx_sysconf(host, proxy_settings)
  File "/Applications/Xcode.app/Contents/Developer/Library/Frameworks/Python3.framework/Versions/3.8/lib/python3.8/urllib/request.py", line 2565, in _proxy_bypass_macosx_sysconf
    hostIP = socket.gethostbyname(hostonly)
UnicodeError: encoding with 'idna' codec failed (UnicodeError: label empty or too long)


******************************************************************************************
30/08/2021 00:36:06
Traceback (most recent call last):
  File "/Users/lucabonamino/dev/BruteSniffing_Fisher/main.py", line 21, in main
    session.start()
  File "/Users/lucabonamino/dev/BruteSniffing_Fisher/modules/controller.py", line 73, in start
    elif x > max_index(self.dire.dict):
  File "/Users/lucabonamino/dev/BruteSniffing_Fisher/modules/controller.py", line 16, in max_index
    del dictionary[98]
KeyError: 98


******************************************************************************************
30/08/2021 00:36:21
Traceback (most recent call last):
  File "/Users/lucabonamino/dev/BruteSniffing_Fisher/main.py", line 21, in main
    session.start()
  File "/Users/lucabonamino/dev/BruteSniffing_Fisher/modules/controller.py", line 73, in start
    elif x > max_index(self.dire.dict):
  File "/Users/lucabonamino/dev/BruteSniffing_Fisher/modules/controller.py", line 16, in max_index
    del dictionary[98]
KeyError: 98


******************************************************************************************
30/08/2021 01:22:43
Traceback (most recent call last):
  File "main.py", line 21, in main
    session.start()
  File "/Users/lucabonamino/dev/BruteSniffing_Fisher/modules/controller.py", line 73, in start
    elif x > max_index(self.dire.dict):
  File "/Users/lucabonamino/dev/BruteSniffing_Fisher/modules/controller.py", line 16, in max_index
    del dictionary[98]
KeyError: 98


******************************************************************************************
30/08/2021 01:23:05
Traceback (most recent call last):
  File "main.py", line 21, in main
    session.start()
  File "/Users/lucabonamino/dev/BruteSniffing_Fisher/modules/controller.py", line 73, in start
    elif x > max_index(self.dire.dict):
  File "/Users/lucabonamino/dev/BruteSniffing_Fisher/modules/controller.py", line 16, in max_index
    del dictionary[98]
KeyError: 98


******************************************************************************************
30/08/2021 01:23:51
Traceback (most recent call last):
  File "main.py", line 21, in main
    session.start()
  File "/Users/lucabonamino/dev/BruteSniffing_Fisher/modules/controller.py", line 73, in start
    elif x > max_index(self.dire.dict):
  File "/Users/lucabonamino/dev/BruteSniffing_Fisher/modules/controller.py", line 16, in max_index
    del dictionary[98]
KeyError: 98


******************************************************************************************
30/08/2021 01:25:56
Traceback (most recent call last):
  File "main.py", line 21, in main
    session.start()
  File "/Users/lucabonamino/dev/BruteSniffing_Fisher/modules/controller.py", line 84, in start
    self.attack.run()
  File "/Users/lucabonamino/dev/BruteSniffing_Fisher/modules/controller.py", line 97, in run
    attack.run()
  File "/Users/lucabonamino/dev/BruteSniffing_Fisher/modules/Attack/core.py", line 35, in run
    class_.run()
TypeError: run() missing 1 required positional argument: 'self'


******************************************************************************************
30/08/2021 01:48:12
Traceback (most recent call last):
  File "main.py", line 21, in main
    session.start()
  File "/Users/lucabonamino/dev/BruteSniffing_Fisher/modules/controller.py", line 84, in start
    self.attack.run()
  File "/Users/lucabonamino/dev/BruteSniffing_Fisher/modules/controller.py", line 97, in run
    attack.run()
  File "/Users/lucabonamino/dev/BruteSniffing_Fisher/modules/Attack/core.py", line 35, in run
    class_.run()
  File "/Users/lucabonamino/dev/BruteSniffing_Fisher/modules/Attack/BruteForce/bruteforce.py", line 17, in run
    run()
  File "/Users/lucabonamino/dev/BruteSniffing_Fisher/modules/Attack/BruteForce/bruteforce.py", line 157, in run
    file = open(pass_file, 'r')
FileNotFoundError: [Errno 2] No such file or directory: 'data/BruteForce/bonamino.luca'


